connected1
python3: no process found
connected2
python3: no process found
connected3
python3: no process found
connected4
exec
printing
Traceback (most recent call last):
  File "master.py", line 43, in <module>
    score(0,id,1,0)
  File "master.py", line 31, in score
    s.connect((HOST, PORT))
ConnectionRefusedError: [Errno 111] Connection refused
Traceback (most recent call last):
  File "<stdin>", line 43, in <module>
  File "<stdin>", line 31, in score
ConnectionRefusedError: [Errno 111] Connection refused
Traceback (most recent call last):
  File "<stdin>", line 43, in <module>
  File "<stdin>", line 31, in score
ConnectionRefusedError: [Errno 111] Connection refused
Traceback (most recent call last):
  File "<stdin>", line 43, in <module>
  File "<stdin>", line 31, in score
ConnectionRefusedError: [Errno 111] Connection refused
./exec-py: line 18:  1701 Terminated              python identifyloc.py
